Workbook

Sheet Sheet1
A1: Task Tracker Export for Client Name (COID) : Sempra Energy (G3AWJ7PAVPW7ZPAD) ; CLIENT ID: 8c5ad7ef-d24b-4e9f-9b5f-0cee02f2564c ; FEIN: ALL ; State: EmpNeedAttn ; Category: Form_issues ; Issues: ALL ; Search: ;Report Date & Time: 04/12/2022 13:03:25 PM .CONFIDENTIAL. Contains personal information. For internal use only.
A2: Last Name | B2: First Name | C2: Employee ID | D2: FEIN | E2: Tax Year | F2: Issue | G2: Actual Offer Date | H2: Benefit Plan Year | I2: Most Recent Import Date | J2: Original Hire Date | K2: Selected Plan Coverage Start/End Date | L2: Selected Plan Name
A3: Abbott | B3: Linda | C3: 59013 | D3: 951240705-SO CAL GAS | E3: 2022 | F3: Individual is enrolled in a COBRA or Retiree plan coverage that was not sent on a current post-enrollment reporting year import | I3: 44653 | K3: 06/01/2020-12/31/9999 | L3: HRA
A4: Abreu | B4: Alberto | C4: 226 | D4: 453699851-SEMPRA INTERNATIONAL LLC | E4: 2022 | F4: Individual is enrolled in a COBRA or Retiree plan coverage that was not sent on a current post-enrollment reporting year import | I4: 44653 | K4: 01/01/2018-12/31/9999 | L4: Anthem Health Care Plus+
A5: Acuna | B5: Tom | C5: 319 | D5: 951184800-SAN DIEGO GAS & ELECTRIC | E5: 2022 | F5: Individual is enrolled in a COBRA or Retiree plan coverage that was not sent on a current post-enrollment reporting year import | I5: 44653 | K5: 01/01/2019-12/31/9999 | L5: HRA
A6: Alleyne | B6: Count | C6: 25409 | D6: 951240705-SO CAL GAS | E6: 2022 | F6: Individual is enrolled in a COBRA or Retiree plan coverage that was not sent on a current post-enrollment reporting year import | I6: 44653 | K6: 01/01/2019-12/31/9999 | L6: Anthem California Care HMO
A7: Alvarado | B7: Juan | C7: 61820 | D7: 951240705-SO CAL GAS | E7: 2022 | F7: Individual is enrolled in a COBRA or Retiree plan coverage that was not sent on a current post-enrollment reporting year import | I7: 44653 | K7: 03/01/2018-12/31/9999 | L7: Anthem California Care HMO
A8: Alvarez | B8: Javier | C8: 1540 | D8: 951184800-SAN DIEGO GAS & ELECTRIC | E8: 2022 | F8: Individual is enrolled in a COBRA or Retiree plan coverage that was not sent on a current post-enrollment reporting year import | I8: 44653 | K8: 08/01/2020-12/31/9999 | L8: HRA
A9: Andalon | B9: Enrique | C9: 39973 | D9: 951240705-SO CAL GAS | E9: 2022 | F9: Individual is enrolled in a COBRA or Retiree plan coverage that was not sent on a current post-enrollment reporting year import | I9: 44653 | K9: 06/01/2020-12/31/9999 | L9: HRA
A10: Anderson | B10: Kimberly | C10: 10079 | D10: 951184800-SAN DIEGO GAS & ELECTRIC | E10: 2022 | F10: Individual is enrolled in a COBRA or Retiree plan coverage that was not sent on a current post-enrollment reporting year import | I10: 44653 | K10: 04/01/2019-12/31/9999 | L10: Anthem Health Care Plus+
A11: Anderson | B11: Richard | C11: 28803 | D11: 951240705-SO CAL GAS | E11: 2022 | F11: Individual is enrolled in a COBRA or Retiree plan coverage that was not sent on a current post-enrollment reporting year import | I11: 44653 | K11: 05/01/2019-12/31/9999 | L11: Anthem Health Care Plus+
A12: Anderson | B12: Terri | C12: 37558 | D12: 951240705-SO CAL GAS | E12: 2022 | F12: Individual is enrolled in a COBRA or Retiree plan coverage that was not sent on a current post-enrollment reporting year import | I12: 44653 | K12: 01/01/2018-12/31/9999 | L12: Anthem PPO Out-of-CA
A13: Andrews | B13: Melissa | C13: 3037 | D13: 951184800-SAN DIEGO GAS & ELECTRIC | E13: 2022 | F13: Individual is enrolled in a COBRA or Retiree plan coverage that was not sent on a current post-enrollment reporting year import | I13: 44653 | K13: 01/01/2018-12/31/9999 | L13: HRA
A14: Arechiga | B14: Corrine | C14: 51794 | D14: 951240705-SO CAL GAS | E14: 2022 | F14: Individual is enrolled in a COBRA or Retiree plan coverage that was not sent on a current post-enrollment reporting year import | I14: 44653 | K14: 06/01/2019-12/31/9999 | L14: HRA
... A39: Bevel | B39: Dexter | C39: 30654 | D39: 951240705-SO CAL GAS | E39: 2022 | F39: Individual is enrolled in a COBRA or Retiree plan coverage that was not sent on a current post-enrollment reporting year import | I39: 44653 | K39: 12/01/2018-01/31/2022 | L39: Anthem California Care HMO
A40: Bilicic | B40: George | C40: C4120 | D40: 330732627-SEMPRA ENERGY | E40: 2022 | F40: Individual is enrolled in a COBRA or Retiree plan coverage that was not sent on a current post-enrollment reporting year import | I40: 44653 | K40: 04/01/2020-12/31/9999 | L40: Anthem Health Care Plus+ *
A41: Bilicic | B41: George | C41: C4120 | D41: 951240705-SO CAL GAS | E41: 2022 | F41: Individual is enrolled in a COBRA or Retiree plan coverage that was not sent on a current post-enrollment reporting year import | I41: 44653 | K41: 04/01/2020-12/31/9999 | L41: Anthem Health Care Plus+ *
A42: Bisetti | B42: Rico | C42: 36165 | D42: 951240705-SO CAL GAS | E42: 2022 | F42: Individual is enrolled in a COBRA or Retiree plan coverage that was not sent on a current post-enrollment reporting year import | I42: 44653 | K42: 01/01/2019-12/31/9999 | L42: Anthem Health Care Plus+
A43: Blaauw | B43: Wynandus | C43: 43153 | D43: 951240705-SO CAL GAS | E43: 2022 | F43: Individual is enrolled in a COBRA or Retiree plan coverage that was not sent on a current post-enrollment reporting year import | I43: 44653 | K43: 10/01/2020-12/31/9999 | L43: HRA
A44: Bland | B44: Greg | C44: 35502 | D44: 951240705-SO CAL GAS | E44: 2022 | F44: Individual is enrolled in a COBRA or Retiree plan coverage that was not sent on a current post-enrollment reporting year import | I44: 44653 | K44: 01/01/2020-12/31/9999 | L44: HRA
A45: Blaser | B45: Kevin | C45: 33392 | D45: 951240705-SO CAL GAS | E45: 2022 | F45: Individual is enrolled in a COBRA or Retiree plan coverage that was not sent on a current post-enrollment reporting year import | I45: 44653 | K45: 10/01/2019-12/31/9999 | L45: Anthem Health Care Plus+
A46: Blaszczynski | B46: Mary | C46: 97099 | D46: 951240705-SO CAL GAS | E46: 2022 | F46: Individual is enrolled in a COBRA or Retiree plan coverage that was not sent on a current post-enrollment reporting year import | I46: 44653 | K46: 10/01/2019-12/31/9999 | L46: Anthem Select HMO
A47: Bliss | B47: Chris | C47: 39503 | D47: 951240705-SO CAL GAS | E47: 2022 | F47: Individual is enrolled in a COBRA or Retiree plan coverage that was not sent on a current post-enrollment reporting year import | I47: 44653 | K47: 01/01/2018-12/31/9999 | L47: Anthem California Care HMO
A48: Blotzer | B48: Dale | C48: 38481 | D48: 951240705-SO CAL GAS | E48: 2022 | F48: Individual is enrolled in a COBRA or Retiree plan coverage that was not sent on a current post-enrollment reporting year import | I48: 44653 | K48: 06/30/2018-12/31/9999 | L48: HRA
A49: Bodwell | B49: Theodore | C49: 57245 | D49: 951240705-SO CAL GAS | E49: 2022 | F49: Individual is enrolled in a COBRA or Retiree plan coverage that was not sent on a current post-enrollment reporting year import | I49: 44653 | K49: 01/01/2019-12/31/9999 | L49: Anthem Select HMO
A50: Bogan | B50: Jennifer | C50: 4943 | D50: 951184800-SAN DIEGO GAS & ELECTRIC | E50: 2022 | F50: Individual is enrolled in a COBRA or Retiree plan coverage that was not sent on a current post-enrollment reporting year import | I50: 44653 | K50: 07/01/2019-12/31/9999 | L50: Anthem Select HMO
A51: Bonner | B51: Stuyvesant | C51: 31544 | D51: 951240705-SO CAL GAS | E51: 2022 | F51: Individual is enrolled in a COBRA or Retiree plan coverage that was not sent on a current post-enrollment reporting year import | I51: 44653 | K51: 09/01/2018-12/31/9999 | L51: Anthem Health Care Plus+
A52: Bosley | B52: Lorrietta | C52: 224 | D52: 951184800-SAN DIEGO GAS & ELECTRIC | E52: 2022 | F52: Individual is enrolled in a COBRA or Retiree plan coverage that was not sent on a current post-enrollment reporting year import | I52: 44653 | K52: 07/01/2020-12/31/9999 | L52: Anthem Health Care Plus+
A53: Bourne | B53: Edgar | C53: 40843 | D53: 951240705-SO CAL GAS | E53: 2022 | F53: Individual is enrolled in a COBRA or Retiree plan coverage that was not sent on a current post-enrollment reporting year import | I53: 44653 | K53: 01/01/2018-12/31/9999 | L53: Anthem Select HMO
... A189: Guerra | B189: Robert | C189: 34796 | D189: 951240705-SO CAL GAS | E189: 2022 | F189: Individual is enrolled in a COBRA or Retiree plan coverage that was not sent on a current post-enrollment reporting year import | I189: 44653 | K189: 07/01/2020-12/31/9999 | L189: Anthem California Care HMO
A190: Guillen | B190: Abraham | C190: E1757 | D190: 951240705-SO CAL GAS | E190: 2022 | F190: Employee has an offer prior to being hired | G190: 44562 | H190: 01/01/2022-12/31/2022 | J190: 44594
A191: Gullo | B191: Russell | C191: 71236 | D191: 951240705-SO CAL GAS | E191: 2022 | F191: Individual is enrolled in a COBRA or Retiree plan coverage that was not sent on a current post-enrollment reporting year import | I191: 44653 | K191: 03/01/2018-12/31/9999 | L191: Anthem Select Plus HMO
A192: Guthrie | B192: Barbara | C192: 34255 | D192: 951184800-SAN DIEGO GAS & ELECTRIC | E192: 2022 | F192: Individual is enrolled in a COBRA or Retiree plan coverage that was not sent on a current post-enrollment reporting year import | I192: 44653 | K192: 01/01/2019-12/31/9999 | L192: Anthem Select HMO
A193: Gutierrez | B193: Maria | C193: 32435 | D193: 330732627-SEMPRA ENERGY | E193: 2022 | F193: Individual is enrolled in a COBRA or Retiree plan coverage that was not sent on a current post-enrollment reporting year import | I193: 44653 | K193: 09/01/2019-12/31/9999 | L193: Anthem Health Care Plus+
A194: Haas | B194: Monica | C194: 34325 | D194: 954673646-SEMPRA SERVICES CORPORATION | E194: 2022 | F194: Individual is enrolled in a COBRA or Retiree plan coverage that was not sent on a current post-enrollment reporting year import | I194: 44653 | K194: 06/01/2018-12/31/9999 | L194: Anthem Health Care Plus+
A195: Haas | B195: Monica | C195: 34325 | D195: 453715016-SEMPRA INFRASTRUCTURE LLC | E195: 2022 | F195: Individual is enrolled in a COBRA or Retiree plan coverage that was not sent on a current post-enrollment reporting year import | I195: 44653 | K195: 06/01/2018-12/31/9999 | L195: Anthem Health Care Plus+
A196: Hackett | B196: Lorinda | C196: 52191 | D196: 951240705-SO CAL GAS | E196: 2022 | F196: Individual is enrolled in a COBRA or Retiree plan coverage that was not sent on a current post-enrollment reporting year import | I196: 44653 | K196: 01/01/2019-12/31/9999 | L196: Anthem California Care HMO
A197: Haddow | B197: Gregory | C197: 34383 | D197: 951184800-SAN DIEGO GAS & ELECTRIC | E197: 2022 | F197: Individual is enrolled in a COBRA or Retiree plan coverage that was not sent on a current post-enrollment reporting year import | I197: 44653 | K197: 02/01/2019-12/31/9999 | L197: HRA
A198: Hadi | B198: Mohammad | C198: 9814 | D198: 951184800-SAN DIEGO GAS & ELECTRIC | E198: 2022 | F198: Individual is enrolled in a COBRA or Retiree plan coverage that was not sent on a current post-enrollment reporting year import | I198: 44653 | K198: 10/01/2020-12/31/9999 | L198: HRA
A199: Hale | B199: Stephen | C199: 52692 | D199: 951240705-SO CAL GAS | E199: 2022 | F199: Individual is enrolled in a COBRA or Retiree plan coverage that was not sent on a current post-enrollment reporting year import | I199: 44653 | K199: 01/01/2019-12/31/9999 | L199: Anthem California Care HMO
...

Sheet Sheet2
A1: EmployeeID | B1: TaxIDNumber | C1: FirstName | D1: LastName | E1: ShortDesc | F1: EffectiveDate | H1: Address | I1: Last Name | J1: First Name | K1: Employee ID | L1: FEIN | M1: Tax Year | N1: Issue | O1: Actual Offer Date | P1: Benefit Plan Year | Q1: Most Recent Import Date | R1: Original Hire Date | S1: Selected Plan Coverage Start/End Date | T1: Selected Plan Name
A2: 39055 | B2: 553651176 | C2: THOMAS | D2: TRAN | E2: Kaiser Permanente Senior Advantage HMO | F2: 44531 | H2: {=CELL("address",_xlfn.XLOOKUP(A2,Sheet1!C:C,Sheet1!C:C))} -> [match.xlsx]Sheet1!$C$542 | I2: {=_xlfn.XLOOKUP(A2,Sheet1!C:C,Sheet1!A:L)} -> Tran | J2: Tri | K2: 39055 | L2: 951240705-SO CAL GAS | M2: 2022 | N2: Individual is enrolled in a COBRA or Retiree plan coverage that was not sent on a current post-enrollment reporting year import | Q2: 44653 | S2: 02/01/2020-12/31/9999 | T2: Anthem Select HMO
A3: 34214 | B3: 547537341 | C3: KEITH | D3: FISHER | E3: Anthem California Care HMO | F3: 43101 | H3: {=CELL("address",_xlfn.XLOOKUP(A3,Sheet1!C:C,Sheet1!C:C))} -> [match.xlsx]Sheet1!$C$148 | I3: {=_xlfn.XLOOKUP(A3,Sheet1!C:C,Sheet1!A:L)} -> Fisher | J3: Keith | K3: 34214 | L3: 951240705-SO CAL GAS | M3: 2022 | N3: Individual is enrolled in a COBRA or Retiree plan coverage that was not sent on a current post-enrollment reporting year import | Q3: 44653 | S3: 01/01/2018-12/31/9999 | T3: Anthem California Care HMO
A4: 38664 | B4: 553150853 | C4: PATRICIA | D4: ANTHONY | E4: Anthem California Care HMO | F4: 43101 | H4: {=CELL("address",_xlfn.XLOOKUP(A4,Sheet1!C:C,Sheet1!C:C))} -> [match.xlsx]Sheet1!$C$444 | I4: {=_xlfn.XLOOKUP(A4,Sheet1!C:C,Sheet1!A:L)} -> Roberts | J4: Patricia | K4: 38664 | L4: 951240705-SO CAL GAS | M4: 2022 | N4: Individual is enrolled in a COBRA or Retiree plan coverage that was not sent on a current post-enrollment reporting year import | Q4: 44653 | S4: 01/01/2018-12/31/9999 | T4: Anthem California Care HMO
A5: 33932 | B5: 547152378 | C5: FRANK | D5: FRUTOS | E5: Anthem Select HMO | F5: 43466 | H5: {=CELL("address",_xlfn.XLOOKUP(A5,Sheet1!C:C,Sheet1!C:C))} -> [match.xlsx]Sheet1!$C$163 | I5: {=_xlfn.XLOOKUP(A5,Sheet1!C:C,Sheet1!A:L)} -> Frutos | J5: Frank | K5: 33932 | L5: 951240705-SO CAL GAS | M5: 2022 | N5: Individual is enrolled in a COBRA or Retiree plan coverage that was not sent on a current post-enrollment reporting year import | Q5: 44653 | S5: 01/01/2019-12/31/9999 | T5: Anthem Select HMO
A6: 26576 | B6: 223946982 | C6: TIJUANNA | D6: JARNAGIN | E6: Anthem Health Care Plus+ | F6: 43466 | H6: {=CELL("address",_xlfn.XLOOKUP(A6,Sheet1!C:C,Sheet1!C:C))} -> [match.xlsx]Sheet1!$C$240 | I6: {=_xlfn.XLOOKUP(A6,Sheet1!C:C,Sheet1!A:L)} -> Jarnagin | J6: Tijuanna | K6: 26576 | L6: 951240705-SO CAL GAS | M6: 2022 | N6: Individual is enrolled in a COBRA or Retiree plan coverage that was not sent on a current post-enrollment reporting year import | Q6: 44653 | S6: 01/01/2019-12/31/9999 | T6: Anthem Health Care Plus+
A7: 54126 | B7: 572929341 | C7: Eddie | D7: Ortega | E7: Anthem California Care HMO | F7: 43556 | H7: {=CELL("address",_xlfn.XLOOKUP(A7,Sheet1!C:C,Sheet1!C:C))} -> [match.xlsx]Sheet1!$C$402 | I7: {=_xlfn.XLOOKUP(A7,Sheet1!C:C,Sheet1!A:L)} -> Ortega | J7: Eddie | K7: 54126 | L7: 951240705-SO CAL GAS | M7: 2022 | N7: Individual is enrolled in a COBRA or Retiree plan coverage that was not sent on a current post-enrollment reporting year import | Q7: 44653 | S7: 04/01/2019-12/31/9999 | T7: Anthem California Care HMO
A8: 45111 | B8: 561356510 | C8: James | D8: Reidy | E8: Anthem California Care HMO | F8: 43132 | H8: {=CELL("address",_xlfn.XLOOKUP(A8,Sheet1!C:C,Sheet1!C:C))} -> [match.xlsx]Sheet1!$C$431 | I8: {=_xlfn.XLOOKUP(A8,Sheet1!C:C,Sheet1!A:L)} -> Reidy | J8: James | K8: 45111 | L8: 951240705-SO CAL GAS | M8: 2022 | N8: Individual is enrolled in a COBRA or Retiree plan coverage that was not sent on a current post-enrollment reporting year import | Q8: 44653 | S8: 02/01/2018-12/31/9999 | T8: Anthem California Care HMO
A9: 37069 | B9: 551080940 | C9: ARTHUR | D9: SENA | E9: Anthem Health Care Plus+ | F9: 43252 | H9: {=CELL("address",_xlfn.XLOOKUP(A9,Sheet1!C:C,Sheet1!C:C))} -> [match.xlsx]Sheet1!$C$486 | I9: {=_xlfn.XLOOKUP(A9,Sheet1!C:C,Sheet1!A:L)} -> Sena | J9: Arthur | K9: 37069 | L9: 951240705-SO CAL GAS | M9: 2022 | N9: Individual is enrolled in a COBRA or Retiree plan coverage that was not sent on a current post-enrollment reporting year import | Q9: 44653 | S9: 06/01/2018-12/31/9999 | T9: Anthem Health Care Plus+
A10: 41027 | B10: 556297286 | C10: VIRGINIA | D10: SKIDMORE | E10: Anthem Health Care Plus+ | F10: 43101 | H10: {=CELL("address",_xlfn.XLOOKUP(A10,Sheet1!C:C,Sheet1!C:C))} -> [match.xlsx]Sheet1!$C$495 | I10: {=_xlfn.XLOOKUP(A10,Sheet1!C:C,Sheet1!A:L)} -> Skidmore | J10: Virginia | K10: 41027 | L10: 951240705-SO CAL GAS | M10: 2022 | N10: Individual is enrolled in a COBRA or Retiree plan coverage that was not sent on a current post-enrollment reporting year import | Q10: 44653 | S10: 01/01/2018-12/31/9999 | T10: Anthem Health Care Plus+
A11: 39625 | B11: 554515546 | C11: THOMAS | D11: OSTOVICH | E11: Anthem California Care HMO | F11: 43101 | H11: {=CELL("address",_xlfn.XLOOKUP(A11,Sheet1!C:C,Sheet1!C:C))} -> [match.xlsx]Sheet1!$C$404 | I11: {=_xlfn.XLOOKUP(A11,Sheet1!C:C,Sheet1!A:L)} -> Ostovich | J11: Thomas | K11: 39625 | L11: 951240705-SO CAL GAS | M11: 2022 | N11: Individual is enrolled in a COBRA or Retiree plan coverage that was not sent on a current post-enrollment reporting year import | Q11: 44653 | S11: 01/01/2018-12/31/9999 | T11: Anthem California Care HMO
A12: 40928 | B12: 556154270 | C12: Jeffrey | D12: Switzer | E12: Anthem California Care HMO | F12: 43709 | H12: {=CELL("address",_xlfn.XLOOKUP(A12,Sheet1!C:C,Sheet1!C:C))} -> [match.xlsx]Sheet1!$C$526 | I12: {=_xlfn.XLOOKUP(A12,Sheet1!C:C,Sheet1!A:L)} -> Switzer | J12: Jeffrey | K12: 40928 | L12: 951240705-SO CAL GAS | M12: 2022 | N12: Individual is enrolled in a COBRA or Retiree plan coverage that was not sent on a current post-enrollment reporting year import | Q12: 44653 | S12: 09/01/2019-12/31/9999 | T12: Anthem California Care HMO
A13: 47490 | B13: 564334885 | C13: Richard | D13: Gibson | E13: Anthem California Care HMO | F13: 43922 | H13: {=CELL("address",_xlfn.XLOOKUP(A13,Sheet1!C:C,Sheet1!C:C))} -> [match.xlsx]Sheet1!$C$172 | I13: {=_xlfn.XLOOKUP(A13,Sheet1!C:C,Sheet1!A:L)} -> Gibson | J13: Richard | K13: 47490 | L13: 951240705-SO CAL GAS | M13: 2022 | N13: Individual is enrolled in a COBRA or Retiree plan coverage that was not sent on a current post-enrollment reporting year import | Q13: 44653 | S13: 04/01/2020-12/31/9999 | T13: Anthem California Care HMO
... A358: 37077 | B358: 551087043 | C358: Brad | D358: Wingert | E358: UHC Medicare Advantage PPO Plan F | F358: 44743 | H358: {=CELL("address",_xlfn.XLOOKUP(A358,Sheet1!C:C,Sheet1!C:C))} -> [match.xlsx]Sheet1!$C$577 | I358: {=_xlfn.XLOOKUP(A358,Sheet1!C:C,Sheet1!A:L)} -> Wingert | J358: Brad | K358: 37077 | L358: 951240705-SO CAL GAS | M358: 2022 | N358: Individual is enrolled in a COBRA or Retiree plan coverage that was not sent on a current post-enrollment reporting year import | Q358: 44653 | S358: 03/01/2020-12/31/9999 | T358: Anthem Select HMO
